<mujoco>
    <!--  Copyright © 2018, Roboti LLC

          This file is licensed under the MuJoCo Resource License (the "License").
          You may not use this file except in compliance with the License.
          You may obtain a copy of the License at

            https://www.roboti.us/resourcelicense.txt
    -->

    <statistic extent="2" meansize=".05"/>

    <option timestep="0.005" solver="Newton" iterations="30" tolerance="1e-10" jacobian="sparse" cone="pyramidal"/>

    <visual>
        <rgba haze="0.15 0.25 0.35 1"/>
        <quality shadowsize="2048"/>
        <map stiffness="700" shadowscale="0.5" fogstart="10" fogend="15" zfar="40" haze="0.3"/>
    </visual>

    <asset>
        <texture type="skybox" builtin="gradient" rgb1="0.3 0.5 0.7" rgb2="0 0 0" width="512" height="512"/> 
        <texture name="texplane" type="2d" builtin="checker" rgb1=".2 .3 .4" rgb2=".1 0.15 0.2" 
            width="512" height="512" mark="cross" markrgb=".8 .8 .8"/>  
        <material name="matplane" reflectance="0.3" texture="texplane" texrepeat="1 1" texuniform="true"/>
    </asset>

    <worldbody>
        <light directional="true" diffuse=".4 .4 .4" specular="0.1 0.1 0.1" pos="0 0 5.0" dir="0 0 -1" castshadow="false"/>
        <light directional="true" diffuse=".6 .6 .6" specular="0.2 0.2 0.2" pos="0 0 4" dir="0 0 -1"/>

        <geom name="ground" type="plane" size="0 0 1" pos="0 0 0" quat="1 0 0 0" material="matplane" condim="1"/>


        <body name="stick" pos="0 0 0.5" quat="0 0.707 0 0.707">
            <geom size="0.02 0.5" type="capsule" friction="0.2 0.005 0.0001"/>
        </body>

        <body name="gripper_base" pos="0 0 0.05" quat="0 0 0 1">
            <!-- okay, i misunderstood this freejoint thing, free joint makes your body subject to gravity dynamics. by default the object is constrained in a fixed way... -->
            <!-- <freejoint name="base_float"/> -->
            <geom size="0.05 0.1 0.01" type="box" density="2.7"/>
            <joint name="base_joint_x" type="slide" pos="0 0 0" axis="1 0 0" range="-45 45" damping="2" stiffness="100" armature="0.02" />
            <joint name="base_joint_y" type="slide" pos="0 0 0" axis="0 1 0" range="-45 45" damping="2" stiffness="100" armature="0.02" />
            <joint name="base_joint_z" type="slide" pos="0 0 0" axis="0 0 1" range="-45 45" damping="2" stiffness="100" armature="0.02" />
            
            <body name="gripper_finger1" pos="0 -0.08 0.11" quat="0 0 0 1">
                <geom size="0.05 0.02 0.1" type="box" density="2.7"/>
                <joint name="gripper_joint1" type="slide" pos="0 0 -0.1" axis="0 1 0" range="-45 45" damping="2" stiffness="100" armature="0.02" />
            </body>

            <body name="gripper_finger2" pos="0 0.08 0.11" quat="0 0 0 1">
                <geom size="0.05 0.02 0.1" type="box" density="2.7"/>
                <joint name="gripper_joint2" type="slide" pos="0 0 -0.1" axis="0 1 0" range="-45 45" damping="2" stiffness="100" armature="0.02" />
            </body>    
        </body>
        
    </worldbody>

    <include file="cloth_no_skin.xml"/>

    <actuator>
        <motor name="gripper_base_actuator_x"       gear="200" joint="base_joint_x" />
        <!-- <motor name="gripper_base_actuator_y"       gear="200" joint="base_joint_y" /> -->
        <motor name="gripper_base_actuator_z"       gear="200" joint="base_joint_z" />
        <motor name="gripper_fingers_actuator1"       gear="200" joint="gripper_joint1" />
        <motor name="gripper_fingers_actuator2"       gear="200" joint="gripper_joint2" />
    </actuator>
</mujoco>

